2018-02-06 18:14:11,240 ERROR: Exception on /reset_password_request [POST] [in /home/kahll/Flask-Administration/env/lib/python3.4/site-packages/flask/app.py:1560]
Traceback (most recent call last):
  File "/home/kahll/Flask-Administration/env/lib/python3.4/site-packages/flask/app.py", line 1982, in wsgi_app
    response = self.full_dispatch_request()
  File "/home/kahll/Flask-Administration/env/lib/python3.4/site-packages/flask/app.py", line 1614, in full_dispatch_request
    rv = self.handle_user_exception(e)
  File "/home/kahll/Flask-Administration/env/lib/python3.4/site-packages/flask/app.py", line 1517, in handle_user_exception
    reraise(exc_type, exc_value, tb)
  File "/home/kahll/Flask-Administration/env/lib/python3.4/site-packages/flask/_compat.py", line 33, in reraise
    raise value
  File "/home/kahll/Flask-Administration/env/lib/python3.4/site-packages/flask/app.py", line 1612, in full_dispatch_request
    rv = self.dispatch_request()
  File "/home/kahll/Flask-Administration/env/lib/python3.4/site-packages/flask/app.py", line 1598, in dispatch_request
    return self.view_functions[rule.endpoint](**req.view_args)
  File "/home/kahll/Flask-Administration/app/routes.py", line 105, in reset_password_request
    send_password_reset_email(user)
  File "/home/kahll/Flask-Administration/app/email.py", line 17, in send_password_reset_email
    html_body=render_template('email/reset_password.html', user=user, token=token))
  File "/home/kahll/Flask-Administration/app/email.py", line 9, in send_email
    mail.send(msg)
  File "/home/kahll/Flask-Administration/env/lib/python3.4/site-packages/flask_mail.py", line 491, in send
    with self.connect() as connection:
  File "/home/kahll/Flask-Administration/env/lib/python3.4/site-packages/flask_mail.py", line 144, in __enter__
    self.host = self.configure_host()
  File "/home/kahll/Flask-Administration/env/lib/python3.4/site-packages/flask_mail.py", line 165, in configure_host
    host.login(self.mail.username, self.mail.password)
  File "/usr/lib/python3.4/smtplib.py", line 652, in login
    raise SMTPAuthenticationError(code, resp)
smtplib.SMTPAuthenticationError: (534, b'5.7.14 <https://accounts.google.com/signin/continue?sarp=1&scc=1&plt=AKgnsbvY\n5.7.14 it22WIjS0Dc_iShVhN4ZbSFEu_QvFPCFRgI4qj0K8_pfLY1077PBNYjV_4aMe6tQ4CYa7g\n5.7.14 3TuVbSXr1KIBNr0pOudGxY4s72uoofaZJ2LpJI3l6PZU5cKZ3DhVrXE3EiISO-ejkQ8RY4\n5.7.14 YXYEHQWS9eIayV5ZSQ7-N4TCuz6nI6VCmZLVboQgzuVlTds_cjvbUJCWnB61l8zRYPZMfR\n5.7.14 oI5vUPgNVS8lYZpBrQzErz0gZ4Dhc> Please log in via your web browser and\n5.7.14 then try again.\n5.7.14  Learn more at\n5.7.14  https://support.google.com/mail/answer/78754 b79sm6546426wmb.18 - gsmtp')
2018-02-06 18:36:09,679 INFO: Microblog startup [in /home/kahll/Flask-Administration/app/__init__.py:45]
