2018-02-01 21:55:51,423 INFO: Microblog startup [in /home/kahll/Flask-Administration/app/__init__.py:43]
2018-02-01 21:56:15,412 ERROR: Exception on /edit_profile [POST] [in /home/kahll/Flask-Administration/env/lib/python3.4/site-packages/flask/app.py:1560]
Traceback (most recent call last):
  File "/home/kahll/Flask-Administration/env/lib/python3.4/site-packages/sqlalchemy/engine/base.py", line 1193, in _execute_context
    context)
  File "/home/kahll/Flask-Administration/env/lib/python3.4/site-packages/sqlalchemy/engine/default.py", line 507, in do_execute
    cursor.execute(statement, parameters)
sqlite3.IntegrityError: UNIQUE constraint failed: user.username

The above exception was the direct cause of the following exception:

Traceback (most recent call last):
  File "/home/kahll/Flask-Administration/env/lib/python3.4/site-packages/flask/app.py", line 1982, in wsgi_app
    response = self.full_dispatch_request()
  File "/home/kahll/Flask-Administration/env/lib/python3.4/site-packages/flask/app.py", line 1614, in full_dispatch_request
    rv = self.handle_user_exception(e)
  File "/home/kahll/Flask-Administration/env/lib/python3.4/site-packages/flask/app.py", line 1517, in handle_user_exception
    reraise(exc_type, exc_value, tb)
  File "/home/kahll/Flask-Administration/env/lib/python3.4/site-packages/flask/_compat.py", line 33, in reraise
    raise value
  File "/home/kahll/Flask-Administration/env/lib/python3.4/site-packages/flask/app.py", line 1612, in full_dispatch_request
    rv = self.dispatch_request()
  File "/home/kahll/Flask-Administration/env/lib/python3.4/site-packages/flask/app.py", line 1598, in dispatch_request
    return self.view_functions[rule.endpoint](**req.view_args)
  File "/home/kahll/Flask-Administration/env/lib/python3.4/site-packages/flask_login/utils.py", line 261, in decorated_view
    return func(*args, **kwargs)
  File "/home/kahll/Flask-Administration/app/routes.py", line 84, in edit_profile
    db.session.commit()
  File "/home/kahll/Flask-Administration/env/lib/python3.4/site-packages/sqlalchemy/orm/scoping.py", line 153, in do
    return getattr(self.registry(), name)(*args, **kwargs)
  File "/home/kahll/Flask-Administration/env/lib/python3.4/site-packages/sqlalchemy/orm/session.py", line 943, in commit
    self.transaction.commit()
  File "/home/kahll/Flask-Administration/env/lib/python3.4/site-packages/sqlalchemy/orm/session.py", line 467, in commit
    self._prepare_impl()
  File "/home/kahll/Flask-Administration/env/lib/python3.4/site-packages/sqlalchemy/orm/session.py", line 447, in _prepare_impl
    self.session.flush()
  File "/home/kahll/Flask-Administration/env/lib/python3.4/site-packages/sqlalchemy/orm/session.py", line 2243, in flush
    self._flush(objects)
  File "/home/kahll/Flask-Administration/env/lib/python3.4/site-packages/sqlalchemy/orm/session.py", line 2369, in _flush
    transaction.rollback(_capture_exception=True)
  File "/home/kahll/Flask-Administration/env/lib/python3.4/site-packages/sqlalchemy/util/langhelpers.py", line 66, in __exit__
    compat.reraise(exc_type, exc_value, exc_tb)
  File "/home/kahll/Flask-Administration/env/lib/python3.4/site-packages/sqlalchemy/util/compat.py", line 187, in reraise
    raise value
  File "/home/kahll/Flask-Administration/env/lib/python3.4/site-packages/sqlalchemy/orm/session.py", line 2333, in _flush
    flush_context.execute()
  File "/home/kahll/Flask-Administration/env/lib/python3.4/site-packages/sqlalchemy/orm/unitofwork.py", line 391, in execute
    rec.execute(self)
  File "/home/kahll/Flask-Administration/env/lib/python3.4/site-packages/sqlalchemy/orm/unitofwork.py", line 556, in execute
    uow
  File "/home/kahll/Flask-Administration/env/lib/python3.4/site-packages/sqlalchemy/orm/persistence.py", line 177, in save_obj
    mapper, table, update)
  File "/home/kahll/Flask-Administration/env/lib/python3.4/site-packages/sqlalchemy/orm/persistence.py", line 768, in _emit_update_statements
    execute(statement, multiparams)
  File "/home/kahll/Flask-Administration/env/lib/python3.4/site-packages/sqlalchemy/engine/base.py", line 948, in execute
    return meth(self, multiparams, params)
  File "/home/kahll/Flask-Administration/env/lib/python3.4/site-packages/sqlalchemy/sql/elements.py", line 269, in _execute_on_connection
    return connection._execute_clauseelement(self, multiparams, params)
  File "/home/kahll/Flask-Administration/env/lib/python3.4/site-packages/sqlalchemy/engine/base.py", line 1060, in _execute_clauseelement
    compiled_sql, distilled_params
  File "/home/kahll/Flask-Administration/env/lib/python3.4/site-packages/sqlalchemy/engine/base.py", line 1200, in _execute_context
    context)
  File "/home/kahll/Flask-Administration/env/lib/python3.4/site-packages/sqlalchemy/engine/base.py", line 1413, in _handle_dbapi_exception
    exc_info
  File "/home/kahll/Flask-Administration/env/lib/python3.4/site-packages/sqlalchemy/util/compat.py", line 203, in raise_from_cause
    reraise(type(exception), exception, tb=exc_tb, cause=cause)
  File "/home/kahll/Flask-Administration/env/lib/python3.4/site-packages/sqlalchemy/util/compat.py", line 186, in reraise
    raise value.with_traceback(tb)
  File "/home/kahll/Flask-Administration/env/lib/python3.4/site-packages/sqlalchemy/engine/base.py", line 1193, in _execute_context
    context)
  File "/home/kahll/Flask-Administration/env/lib/python3.4/site-packages/sqlalchemy/engine/default.py", line 507, in do_execute
    cursor.execute(statement, parameters)
sqlalchemy.exc.IntegrityError: (sqlite3.IntegrityError) UNIQUE constraint failed: user.username [SQL: 'UPDATE user SET username=?, about_me=? WHERE user.id = ?'] [parameters: ('susan', 'DESCRIPTION', 2)] (Background on this error at: http://sqlalche.me/e/gkpj)
2018-02-05 06:57:39,137 INFO: Microblog startup [in /home/kahll/Flask-Administration/app/__init__.py:43]
2018-02-05 07:22:55,677 INFO: Microblog startup [in /home/kahll/Flask-Administration/app/__init__.py:43]
2018-02-05 13:50:43,719 INFO: Microblog startup [in /home/kahll/Flask-Administration/app/__init__.py:43]
2018-02-05 13:50:53,923 ERROR: Exception on /index [POST] [in /home/kahll/Flask-Administration/env/lib/python3.4/site-packages/flask/app.py:1560]
Traceback (most recent call last):
  File "/home/kahll/Flask-Administration/env/lib/python3.4/site-packages/flask/app.py", line 1982, in wsgi_app
    response = self.full_dispatch_request()
  File "/home/kahll/Flask-Administration/env/lib/python3.4/site-packages/flask/app.py", line 1614, in full_dispatch_request
    rv = self.handle_user_exception(e)
  File "/home/kahll/Flask-Administration/env/lib/python3.4/site-packages/flask/app.py", line 1517, in handle_user_exception
    reraise(exc_type, exc_value, tb)
  File "/home/kahll/Flask-Administration/env/lib/python3.4/site-packages/flask/_compat.py", line 33, in reraise
    raise value
  File "/home/kahll/Flask-Administration/env/lib/python3.4/site-packages/flask/app.py", line 1612, in full_dispatch_request
    rv = self.dispatch_request()
  File "/home/kahll/Flask-Administration/env/lib/python3.4/site-packages/flask/app.py", line 1598, in dispatch_request
    return self.view_functions[rule.endpoint](**req.view_args)
  File "/home/kahll/Flask-Administration/env/lib/python3.4/site-packages/flask_login/utils.py", line 261, in decorated_view
    return func(*args, **kwargs)
  File "/home/kahll/Flask-Administration/app/routes.py", line 15, in index
    post = Post(body=form.post.data, author=current_user)
  File "<string>", line 4, in __init__
  File "/home/kahll/Flask-Administration/env/lib/python3.4/site-packages/sqlalchemy/orm/state.py", line 417, in _initialize_instance
    manager.dispatch.init_failure(self, args, kwargs)
  File "/home/kahll/Flask-Administration/env/lib/python3.4/site-packages/sqlalchemy/util/langhelpers.py", line 66, in __exit__
    compat.reraise(exc_type, exc_value, exc_tb)
  File "/home/kahll/Flask-Administration/env/lib/python3.4/site-packages/sqlalchemy/util/compat.py", line 187, in reraise
    raise value
  File "/home/kahll/Flask-Administration/env/lib/python3.4/site-packages/sqlalchemy/orm/state.py", line 414, in _initialize_instance
    return manager.original_init(*mixed[1:], **kwargs)
  File "/home/kahll/Flask-Administration/env/lib/python3.4/site-packages/sqlalchemy/ext/declarative/base.py", line 699, in _declarative_constructor
    (k, cls_.__name__))
TypeError: 'author' is an invalid keyword argument for Post
2018-02-05 13:59:35,131 INFO: Microblog startup [in /home/kahll/Flask-Administration/app/__init__.py:43]
2018-02-05 14:14:37,860 INFO: Microblog startup [in /home/kahll/Flask-Administration/app/__init__.py:43]
2018-02-05 14:20:41,443 INFO: Microblog startup [in /home/kahll/Flask-Administration/app/__init__.py:43]
2018-02-05 14:34:22,621 INFO: Microblog startup [in /home/kahll/Flask-Administration/app/__init__.py:43]
2018-02-05 14:39:39,810 INFO: Microblog startup [in /home/kahll/Flask-Administration/app/__init__.py:43]
2018-02-06 10:19:09,662 INFO: Microblog startup [in /home/kahll/Flask-Administration/app/__init__.py:43]
