2018-02-06 18:14:11,240 ERROR: Exception on /reset_password_request [POST] [in /home/kahll/Flask-Administration/env/lib/python3.4/site-packages/flask/app.py:1560]
Traceback (most recent call last):
  File "/home/kahll/Flask-Administration/env/lib/python3.4/site-packages/flask/app.py", line 1982, in wsgi_app
    response = self.full_dispatch_request()
  File "/home/kahll/Flask-Administration/env/lib/python3.4/site-packages/flask/app.py", line 1614, in full_dispatch_request
    rv = self.handle_user_exception(e)
  File "/home/kahll/Flask-Administration/env/lib/python3.4/site-packages/flask/app.py", line 1517, in handle_user_exception
    reraise(exc_type, exc_value, tb)
  File "/home/kahll/Flask-Administration/env/lib/python3.4/site-packages/flask/_compat.py", line 33, in reraise
    raise value
  File "/home/kahll/Flask-Administration/env/lib/python3.4/site-packages/flask/app.py", line 1612, in full_dispatch_request
    rv = self.dispatch_request()
  File "/home/kahll/Flask-Administration/env/lib/python3.4/site-packages/flask/app.py", line 1598, in dispatch_request
    return self.view_functions[rule.endpoint](**req.view_args)
  File "/home/kahll/Flask-Administration/app/routes.py", line 105, in reset_password_request
    send_password_reset_email(user)
  File "/home/kahll/Flask-Administration/app/email.py", line 17, in send_password_reset_email
    html_body=render_template('email/reset_password.html', user=user, token=token))
  File "/home/kahll/Flask-Administration/app/email.py", line 9, in send_email
    mail.send(msg)
  File "/home/kahll/Flask-Administration/env/lib/python3.4/site-packages/flask_mail.py", line 491, in send
    with self.connect() as connection:
  File "/home/kahll/Flask-Administration/env/lib/python3.4/site-packages/flask_mail.py", line 144, in __enter__
    self.host = self.configure_host()
  File "/home/kahll/Flask-Administration/env/lib/python3.4/site-packages/flask_mail.py", line 165, in configure_host
    host.login(self.mail.username, self.mail.password)
  File "/usr/lib/python3.4/smtplib.py", line 652, in login
    raise SMTPAuthenticationError(code, resp)
smtplib.SMTPAuthenticationError: (534, b'5.7.14 <https://accounts.google.com/signin/continue?sarp=1&scc=1&plt=AKgnsbvY\n5.7.14 it22WIjS0Dc_iShVhN4ZbSFEu_QvFPCFRgI4qj0K8_pfLY1077PBNYjV_4aMe6tQ4CYa7g\n5.7.14 3TuVbSXr1KIBNr0pOudGxY4s72uoofaZJ2LpJI3l6PZU5cKZ3DhVrXE3EiISO-ejkQ8RY4\n5.7.14 YXYEHQWS9eIayV5ZSQ7-N4TCuz6nI6VCmZLVboQgzuVlTds_cjvbUJCWnB61l8zRYPZMfR\n5.7.14 oI5vUPgNVS8lYZpBrQzErz0gZ4Dhc> Please log in via your web browser and\n5.7.14 then try again.\n5.7.14  Learn more at\n5.7.14  https://support.google.com/mail/answer/78754 b79sm6546426wmb.18 - gsmtp')
2018-02-06 18:36:09,679 INFO: Microblog startup [in /home/kahll/Flask-Administration/app/__init__.py:45]
2018-02-06 18:54:22,757 INFO: Microblog startup [in /home/kahll/Flask-Administration/app/__init__.py:47]
2018-02-07 10:18:17,224 INFO: Microblog startup [in /home/kahll/Flask-Administration/app/__init__.py:47]
2018-02-07 12:04:46,759 INFO: Microblog startup [in /home/kahll/Flask-Administration/app/__init__.py:47]
2018-02-07 12:08:25,766 INFO: Microblog startup [in /home/kahll/Flask-Administration/app/__init__.py:47]
2018-02-07 12:19:57,085 INFO: Microblog startup [in /home/kahll/Flask-Administration/app/__init__.py:47]
2018-02-07 12:29:54,433 INFO: Microblog startup [in /home/kahll/Flask-Administration/app/__init__.py:49]
2018-02-07 12:30:22,255 ERROR: Exception on /user/ludo [GET] [in /home/kahll/Flask-Administration/env/lib/python3.4/site-packages/flask/app.py:1560]
Traceback (most recent call last):
  File "/home/kahll/Flask-Administration/env/lib/python3.4/site-packages/flask/app.py", line 1982, in wsgi_app
    response = self.full_dispatch_request()
  File "/home/kahll/Flask-Administration/env/lib/python3.4/site-packages/flask/app.py", line 1614, in full_dispatch_request
    rv = self.handle_user_exception(e)
  File "/home/kahll/Flask-Administration/env/lib/python3.4/site-packages/flask/app.py", line 1517, in handle_user_exception
    reraise(exc_type, exc_value, tb)
  File "/home/kahll/Flask-Administration/env/lib/python3.4/site-packages/flask/_compat.py", line 33, in reraise
    raise value
  File "/home/kahll/Flask-Administration/env/lib/python3.4/site-packages/flask/app.py", line 1612, in full_dispatch_request
    rv = self.dispatch_request()
  File "/home/kahll/Flask-Administration/env/lib/python3.4/site-packages/flask/app.py", line 1598, in dispatch_request
    return self.view_functions[rule.endpoint](**req.view_args)
  File "/home/kahll/Flask-Administration/env/lib/python3.4/site-packages/flask_login/utils.py", line 261, in decorated_view
    return func(*args, **kwargs)
  File "/home/kahll/Flask-Administration/app/routes.py", line 73, in user
    return render_template('user.html', user=user, posts=posts)
  File "/home/kahll/Flask-Administration/env/lib/python3.4/site-packages/flask/templating.py", line 134, in render_template
    context, ctx.app)
  File "/home/kahll/Flask-Administration/env/lib/python3.4/site-packages/flask/templating.py", line 116, in _render
    rv = template.render(context)
  File "/home/kahll/Flask-Administration/env/lib/python3.4/site-packages/jinja2/environment.py", line 1008, in render
    return self.environment.handle_exception(exc_info, True)
  File "/home/kahll/Flask-Administration/env/lib/python3.4/site-packages/jinja2/environment.py", line 780, in handle_exception
    reraise(exc_type, exc_value, tb)
  File "/home/kahll/Flask-Administration/env/lib/python3.4/site-packages/jinja2/_compat.py", line 37, in reraise
    raise value.with_traceback(tb)
  File "/home/kahll/Flask-Administration/app/templates/user.html", line 1, in top-level template code
    {% extends "base.html" %}
  File "/home/kahll/Flask-Administration/app/templates/base.html", line 1, in top-level template code
    {% extends 'bootstrap/base.html' %}
  File "/home/kahll/Flask-Administration/env/lib/python3.4/site-packages/flask_bootstrap/templates/bootstrap/base.html", line 1, in top-level template code
    {% block doc -%}
  File "/home/kahll/Flask-Administration/env/lib/python3.4/site-packages/flask_bootstrap/templates/bootstrap/base.html", line 4, in block "doc"
    {%- block html %}
  File "/home/kahll/Flask-Administration/env/lib/python3.4/site-packages/flask_bootstrap/templates/bootstrap/base.html", line 20, in block "html"
    {% block body -%}
  File "/home/kahll/Flask-Administration/env/lib/python3.4/site-packages/flask_bootstrap/templates/bootstrap/base.html", line 23, in block "body"
    {% block content -%}
  File "/home/kahll/Flask-Administration/app/templates/base.html", line 46, in block "content"
    {% block app_content %}
  File "/home/kahll/Flask-Administration/app/templates/user.html", line 17, in block "app_content"
    {% include '_post.html' %}
  File "/home/kahll/Flask-Administration/app/templates/_post.html", line 12, in top-level template code
    sayd {{ moment(post.timestamp).fromNow() }}:<br>
  File "/home/kahll/Flask-Administration/env/lib/python3.4/site-packages/flask_moment.py", line 86, in fromNow
    return self._render("fromNow(%s)" % int(no_suffix), refresh)
  File "/home/kahll/Flask-Administration/env/lib/python3.4/site-packages/flask_moment.py", line 76, in _render
    t = self._timestamp_as_iso_8601(self.timestamp)
  File "/home/kahll/Flask-Administration/env/lib/python3.4/site-packages/flask_moment.py", line 73, in _timestamp_as_iso_8601
    return timestamp.strftime('%Y-%m-%dT%H:%M:%S' + tz)
jinja2.exceptions.UndefinedError: 'dict object' has no attribute 'timestamp'
2018-02-07 12:33:34,862 INFO: Microblog startup [in /home/kahll/Flask-Administration/app/__init__.py:49]
